Workbook
Name DataSourceTable: #REF!
Name DataSourceTable: #REF!
Name DataSourceTable: #REF!
Name pangit: #REF!
Name pangit: #REF!
Name pangit: #REF!

Sheet Data Source
A1: RegistryNum | B1: DocumentStatus | C1: CFirstName | D1: CMiddleName | E1: CLastName | F1: CSexId | G1: CBirthDate | H1: CBirthAddress | I1: CBirthMunicipality | J1: CBirthMunicipalityId | K1: CBirthProvince | L1: CBirthProvinceId | M1: CBirthCountry | N1: CBirthCountryId | O1: CBirthTypeId | P1: MFirstName | Q1: MMiddleName | R1: MLastName | S1: MCitizenship | T1: MCitizenshipId | U1: MOccupation | V1: MOccupationId | W1: MAge | X1: MAddress | Y1: MMunicipality | Z1: MMunicipalityId | AA1: MProvince | AB1: MProvinceId | AC1: MCountry | AD1: MCountryId | AE1: FFirstName | AF1: FMiddleName | AG1: FLastName | AH1: FCitizenship | AI1: FCitizenshipId | AJ1: FOccupation | AK1: FOccupationId | AL1: FAge | AM1: FAddress | AN1: FMunicipality | AO1: FMunicipalityId | AP1: FProvince | AQ1: FProvinceId | AR1: FCountry | AS1: FCountryId | AT1: AttendantId | AU1: AttendantName | AV1: AttendantTitle | AW1: PreparerName | AX1: PreparerTitle | AY1: PreparerDate | AZ1: DateReceived | BA1: DateRegistered | BB1: Week Number | BC1: Week Start Date | BD1: Week End Date | BE1: Year | BF1: Month | BG1: Day

Sheet Statistic Reports
B2: HEADING 1
B4: HEADING 2
B9: =+'Data Source'!BE2 & " : " & " BIRTH REGISTRATION STATISTICS REPORTS" -> : BIRTH REGISTRATION STATISTICS REPORTS
B12: Birth Registration By Month and By Gender
L13: DON’T DELETE
B14: Month | C14: MALE | D14: Female | E14: TOTAL | L14: Ref. Month No.
B15: January | C15: =++COUNTIFS('Data Source'!$BF:$BF,'Statistic Reports'!$L15,'Data Source'!$F:$F,'Statistic Reports'!C$14) -> 0 | D15: =++COUNTIFS('Data Source'!$BF:$BF,'Statistic Reports'!$L15,'Data Source'!$F:$F,'Statistic Reports'!D$14) -> 0 | E15: =D15+C15 -> 0 | L15: 1
B16: February | C16: =++COUNTIFS('Data Source'!$BF:$BF,'Statistic Reports'!$L16,'Data Source'!$F:$F,'Statistic Reports'!C$14) -> 0 | D16: =++COUNTIFS('Data Source'!$BF:$BF,'Statistic Reports'!$L16,'Data Source'!$F:$F,'Statistic Reports'!D$14) -> 0 | E16: =+D16+C16 -> 0 | L16: 2
B17: March | C17: =++COUNTIFS('Data Source'!$BF:$BF,'Statistic Reports'!$L17,'Data Source'!$F:$F,'Statistic Reports'!C$14) -> 0 | D17: =++COUNTIFS('Data Source'!$BF:$BF,'Statistic Reports'!$L17,'Data Source'!$F:$F,'Statistic Reports'!D$14) -> 0 | E17: =+D17+C17 -> 0 | L17: 3
B18: April | C18: =++COUNTIFS('Data Source'!$BF:$BF,'Statistic Reports'!$L18,'Data Source'!$F:$F,'Statistic Reports'!C$14) -> 0 | D18: =++COUNTIFS('Data Source'!$BF:$BF,'Statistic Reports'!$L18,'Data Source'!$F:$F,'Statistic Reports'!D$14) -> 0 | E18: =+D18+C18 -> 0 | L18: 4
B19: May | C19: =++COUNTIFS('Data Source'!$BF:$BF,'Statistic Reports'!$L19,'Data Source'!$F:$F,'Statistic Reports'!C$14) -> 0 | D19: =++COUNTIFS('Data Source'!$BF:$BF,'Statistic Reports'!$L19,'Data Source'!$F:$F,'Statistic Reports'!D$14) -> 0 | E19: =+D19+C19 -> 0 | L19: 5
B20: June | C20: =++COUNTIFS('Data Source'!$BF:$BF,'Statistic Reports'!$L20,'Data Source'!$F:$F,'Statistic Reports'!C$14) -> 0 | D20: =++COUNTIFS('Data Source'!$BF:$BF,'Statistic Reports'!$L20,'Data Source'!$F:$F,'Statistic Reports'!D$14) -> 0 | E20: =+D20+C20 -> 0 | L20: 6
B21: July | C21: =++COUNTIFS('Data Source'!$BF:$BF,'Statistic Reports'!$L21,'Data Source'!$F:$F,'Statistic Reports'!C$14) -> 0 | D21: =++COUNTIFS('Data Source'!$BF:$BF,'Statistic Reports'!$L21,'Data Source'!$F:$F,'Statistic Reports'!D$14) -> 0 | E21: =+D21+C21 -> 0 | L21: 7
B22: August | C22: =++COUNTIFS('Data Source'!$BF:$BF,'Statistic Reports'!$L22,'Data Source'!$F:$F,'Statistic Reports'!C$14) -> 0 | D22: =++COUNTIFS('Data Source'!$BF:$BF,'Statistic Reports'!$L22,'Data Source'!$F:$F,'Statistic Reports'!D$14) -> 0 | E22: =+D22+C22 -> 0 | L22: 8
B23: September | C23: =++COUNTIFS('Data Source'!$BF:$BF,'Statistic Reports'!$L23,'Data Source'!$F:$F,'Statistic Reports'!C$14) -> 0 | D23: =++COUNTIFS('Data Source'!$BF:$BF,'Statistic Reports'!$L23,'Data Source'!$F:$F,'Statistic Reports'!D$14) -> 0 | E23: =+D23+C23 -> 0 | L23: 9
B24: October | C24: =++COUNTIFS('Data Source'!$BF:$BF,'Statistic Reports'!$L24,'Data Source'!$F:$F,'Statistic Reports'!C$14) -> 0 | D24: =++COUNTIFS('Data Source'!$BF:$BF,'Statistic Reports'!$L24,'Data Source'!$F:$F,'Statistic Reports'!D$14) -> 0 | E24: =+D24+C24 -> 0 | L24: 10
B25: November | C25: =++COUNTIFS('Data Source'!$BF:$BF,'Statistic Reports'!$L25,'Data Source'!$F:$F,'Statistic Reports'!C$14) -> 0 | D25: =++COUNTIFS('Data Source'!$BF:$BF,'Statistic Reports'!$L25,'Data Source'!$F:$F,'Statistic Reports'!D$14) -> 0 | E25: =+D25+C25 -> 0 | L25: 11
B26: December | C26: =++COUNTIFS('Data Source'!$BF:$BF,'Statistic Reports'!$L26,'Data Source'!$F:$F,'Statistic Reports'!C$14) -> 0 | D26: =++COUNTIFS('Data Source'!$BF:$BF,'Statistic Reports'!$L26,'Data Source'!$F:$F,'Statistic Reports'!D$14) -> 0 | E26: =+D26+C26 -> 0 | L26: 12
E27: =+#REF! -> #REF!
B28: Total | C28: =++SUM(C15:C26) -> 0 | D28: =++SUM(D15:D26) -> 0 | E28: =++SUM(E15:E26) -> 0
B71: Mother Age Category with Child Gender
B73: AGE Category | C73: MALE | D73: Female | E73: TOTAL | L73: Ref. Month No.
B74: Belo 15 Years Old | C74: =COUNTIFS('Data Source'!$F:$F,C73,'Data Source'!$W:$W,"<15") -> 0 | D74: =COUNTIFS('Data Source'!$F:$F,D73,'Data Source'!$W:$W,"<15") -> 0 | E74: =+D74+C74 -> 0
B75: 15-19 | C75: =COUNTIFS('Data Source'!$F:$F,C73,'Data Source'!$W:$W,">=15",'Data Source'!$W:$W,"<=19") -> 0 | D75: =COUNTIFS('Data Source'!$F:$F,D73,'Data Source'!$W:$W,">=15",'Data Source'!$W:$W,"<=19") -> 0 | E75: =+D75+C75 -> 0
B76: 20-24 | C76: =COUNTIFS('Data Source'!$F:$F,C73,'Data Source'!$W:$W,">=20",'Data Source'!$W:$W,"<=24") -> 0 | D76: =COUNTIFS('Data Source'!$F:$F,D73,'Data Source'!$W:$W,">=20",'Data Source'!$W:$W,"<=24") -> 0 | E76: =+D76+C76 -> 0
B77: 25-29 | C77: =COUNTIFS('Data Source'!$F:$F,C73,'Data Source'!$W:$W,">=25",'Data Source'!$W:$W,"<=29") -> 0 | D77: =COUNTIFS('Data Source'!$F:$F,D73,'Data Source'!$W:$W,">=25",'Data Source'!$W:$W,"<=29") -> 0 | E77: =+D77+C77 -> 0
B78: 30-34 | C78: =COUNTIFS('Data Source'!$F:$F,C73,'Data Source'!$W:$W,">=30",'Data Source'!$W:$W,"<=34") -> 0 | D78: =COUNTIFS('Data Source'!$F:$F,D73,'Data Source'!$W:$W,">=30",'Data Source'!$W:$W,"<=34") -> 0 | E78: =+D78+C78 -> 0
B79: 35-39 | C79: =COUNTIFS('Data Source'!$F:$F,C73,'Data Source'!$W:$W,">=35",'Data Source'!$W:$W,"<=39") -> 0 | D79: =COUNTIFS('Data Source'!$F:$F,D73,'Data Source'!$W:$W,">=35",'Data Source'!$W:$W,"<=39") -> 0 | E79: =+D79+C79 -> 0
B80: 40-44 | C80: =COUNTIFS('Data Source'!$F:$F,C73,'Data Source'!$W:$W,">=40",'Data Source'!$W:$W,"<=44") -> 0 | D80: =COUNTIFS('Data Source'!$F:$F,D73,'Data Source'!$W:$W,">=40",'Data Source'!$W:$W,"<=44") -> 0 | E80: =+D80+C80 -> 0
B81: 45 and Up | C81: =COUNTIFS('Data Source'!$F:$F,C73,'Data Source'!$W:$W,">=45") -> 0 | D81: =COUNTIFS('Data Source'!$F:$F,D73,'Data Source'!$W:$W,">=45") -> 0 | E81: =+D81+C81 -> 0
B82: Age - Not Stated | C82: =COUNTIFS('Data Source'!$F:$F,C73,'Data Source'!$W:$W,"") -> 0 | D82: =COUNTIFS('Data Source'!$F:$F,D73,'Data Source'!$W:$W,"") -> 0 | E82: =+D82+C82 -> 0
E83: =+#REF! -> #REF!
B84: Total | C84: =++SUM(C74:C82) -> 0 | D84: =++SUM(D74:D82) -> 0 | E84: =++SUM(E74:E82) -> 0
B106: Birth Registration By Attendant Type
B108: ATTENDANT TYPE | C108: MALE | D108: Female | E108: TOTAL
B109: PHYSICIAN | C109: =++COUNTIFS('Data Source'!$F:$F,'Statistic Reports'!C$108,'Data Source'!$AT:$AT,'Statistic Reports'!$B109) -> 0 | D109: =++COUNTIFS('Data Source'!$F:$F,'Statistic Reports'!D$108,'Data Source'!$AT:$AT,'Statistic Reports'!$B109) -> 0 | E109: =++SUM(C109:D109) -> 0
B110: NURSE | C110: =++COUNTIFS('Data Source'!$F:$F,'Statistic Reports'!C$108,'Data Source'!$AT:$AT,'Statistic Reports'!$B110) -> 0 | D110: =++COUNTIFS('Data Source'!$F:$F,'Statistic Reports'!D$108,'Data Source'!$AT:$AT,'Statistic Reports'!$B110) -> 0 | E110: =++SUM(C110:D110) -> 0
B111: OBGYNE | C111: =++COUNTIFS('Data Source'!$F:$F,'Statistic Reports'!C$108,'Data Source'!$AT:$AT,'Statistic Reports'!$B111) -> 0 | D111: =++COUNTIFS('Data Source'!$F:$F,'Statistic Reports'!D$108,'Data Source'!$AT:$AT,'Statistic Reports'!$B111) -> 0 | E111: =++SUM(C111:D111) -> 0
B112: OBSTETRICIAN/ GYNECOLOGIST | C112: =++COUNTIFS('Data Source'!$F:$F,'Statistic Reports'!C$108,'Data Source'!$AT:$AT,'Statistic Reports'!$B112) -> 0 | D112: =++COUNTIFS('Data Source'!$F:$F,'Statistic Reports'!D$108,'Data Source'!$AT:$AT,'Statistic Reports'!$B112) -> 0 | E112: =++SUM(C112:D112) -> 0
B113: MIDWIFE | C113: =++COUNTIFS('Data Source'!$F:$F,'Statistic Reports'!C$108,'Data Source'!$AT:$AT,'Statistic Reports'!$B113) -> 0 | D113: =++COUNTIFS('Data Source'!$F:$F,'Statistic Reports'!D$108,'Data Source'!$AT:$AT,'Statistic Reports'!$B113) -> 0 | E113: =++SUM(C113:D113) -> 0
...

Sheet ByMunicipality
B2: HEADING 1
B4: HEADING 2
B8: MOTHER ADDRESS REPORT
B11: MOTHER MUNICIPALITY SUMMARY
B13: No. | C13: Municipality Name | D13: Province | E13: Country | F13: MALE | G13: FEMALE | H13: TOTAL

Sheet TeenAge
B2: HEADING 1
B4: HEADING 2
B8: TEENAGE PREGNANCY REPORT
B11: BY MUNICIPALITY SUMMARY
B14: No. | C14: Name | F14: Address | G14: TOTAL
