Workbook
Name DataSourceTable: #REF!
Name DataSourceTable: #REF!
Name pangit: #REF!
Name pangit: #REF!

Sheet Data Source
A1: RegistryNum | B1: DocumentStatus | C1: CFirstName | D1: CMiddleName | E1: CLastName | F1: CSexId | G1: CDeathDate | H1: CBirthDate | I1: CAgeYears | J1: CAgeMonths | K1: CAgeDays | L1: CAgeHours | M1: CAgeMinutes | N1: CDeathAddress | O1: CDeathMunicipality | P1: CDeathMunicipalityId | Q1: CDeathProvince | R1: CDeathProvinceId | S1: CDeathCountry | T1: CDeathCountryId | U1: CCivilStatusId | V1: CReligion | W1: CCitizenship | X1: CResidenceAddress | Y1: CResidenceMunicipality | Z1: CResidenceMunicipalityId | AA1: CResidenceProvince | AB1: CResidenceProvinceId | AC1: CResidenceCountry | AD1: CResidenceCountryId | AE1: COccupation | AF1: FFirstName | AG1: FMiddleName | AH1: FLastName | AI1: MFirstName | AJ1: MMiddleName | AK1: MLastName | AL1: CCauseImmediate | AM1: CCauseImmediateId | AN1: CCauseImmediateInterval | AO1: CCauseAntecedent | AP1: CCauseAntecedentId | AQ1: CCauseAntecedentInterval | AR1: CCauseUnderlying | AS1: CCauseUnderlyingId | AT1: CCauseUnderlyingInterval | AU1: CCauseOther | AV1: CCauseOtherId | AW1: AttendantId | AX1: AttendantName | AY1: AttendantTitle | AZ1: AttendantAttendedFrom | BA1: PreparerName | BB1: PreparerTitle | BC1: PreparerDate | BD1: DateReceived | BE1: DateRegistered | BF1: Week Number | BG1: Week Start Date | BH1: Week End Date | BI1: Year | BJ1: Month | BK1: Day | BL1: AgeYearsNumeric | BM1: AgeMonthsNumeric | BN1: AgeDaysNumeric | BO1: AgeHoursNumeric | BP1: AgeMinutesNumeric

Sheet Statistic Reports
B2: HEADING 1
B4: HEADING 2
B9: ='Data Source'!BI2 & " : " & " DEATH REGISTRATION STATISTICS REPORTS" -> : DEATH REGISTRATION STATISTICS REPORTS
B12: Death Registration By Month and By Gender
L13: DON’T DELETE
B14: Month | C14: MALE | D14: Female | E14: TOTAL | L14: Ref. Month No.
B15: January | C15: =++COUNTIFS('Data Source'!$F:$F,'Statistic Reports'!C$14,'Data Source'!$BJ:$BJ,'Statistic Reports'!$L15) -> 0 | D15: =++COUNTIFS('Data Source'!$F:$F,'Statistic Reports'!D$14,'Data Source'!$BJ:$BJ,'Statistic Reports'!$L15) -> 0 | E15: =D15+C15 -> 0 | L15: 1
B16: February | C16: =++COUNTIFS('Data Source'!$F:$F,'Statistic Reports'!C$14,'Data Source'!$BJ:$BJ,'Statistic Reports'!$L16) -> 0 | D16: =++COUNTIFS('Data Source'!$F:$F,'Statistic Reports'!D$14,'Data Source'!$BJ:$BJ,'Statistic Reports'!$L16) -> 0 | E16: =+D16+C16 -> 0 | L16: 2
B17: March | C17: =++COUNTIFS('Data Source'!$F:$F,'Statistic Reports'!C$14,'Data Source'!$BJ:$BJ,'Statistic Reports'!$L17) -> 0 | D17: =++COUNTIFS('Data Source'!$F:$F,'Statistic Reports'!D$14,'Data Source'!$BJ:$BJ,'Statistic Reports'!$L17) -> 0 | E17: =+D17+C17 -> 0 | L17: 3
B18: April | C18: =++COUNTIFS('Data Source'!$F:$F,'Statistic Reports'!C$14,'Data Source'!$BJ:$BJ,'Statistic Reports'!$L18) -> 0 | D18: =++COUNTIFS('Data Source'!$F:$F,'Statistic Reports'!D$14,'Data Source'!$BJ:$BJ,'Statistic Reports'!$L18) -> 0 | E18: =+D18+C18 -> 0 | L18: 4
B19: May | C19: =++COUNTIFS('Data Source'!$F:$F,'Statistic Reports'!C$14,'Data Source'!$BJ:$BJ,'Statistic Reports'!$L19) -> 0 | D19: =++COUNTIFS('Data Source'!$F:$F,'Statistic Reports'!D$14,'Data Source'!$BJ:$BJ,'Statistic Reports'!$L19) -> 0 | E19: =+D19+C19 -> 0 | L19: 5
B20: June | C20: =++COUNTIFS('Data Source'!$F:$F,'Statistic Reports'!C$14,'Data Source'!$BJ:$BJ,'Statistic Reports'!$L20) -> 0 | D20: =++COUNTIFS('Data Source'!$F:$F,'Statistic Reports'!D$14,'Data Source'!$BJ:$BJ,'Statistic Reports'!$L20) -> 0 | E20: =+D20+C20 -> 0 | L20: 6
B21: July | C21: =++COUNTIFS('Data Source'!$F:$F,'Statistic Reports'!C$14,'Data Source'!$BJ:$BJ,'Statistic Reports'!$L21) -> 0 | D21: =++COUNTIFS('Data Source'!$F:$F,'Statistic Reports'!D$14,'Data Source'!$BJ:$BJ,'Statistic Reports'!$L21) -> 0 | E21: =+D21+C21 -> 0 | L21: 7
B22: August | C22: =++COUNTIFS('Data Source'!$F:$F,'Statistic Reports'!C$14,'Data Source'!$BJ:$BJ,'Statistic Reports'!$L22) -> 0 | D22: =++COUNTIFS('Data Source'!$F:$F,'Statistic Reports'!D$14,'Data Source'!$BJ:$BJ,'Statistic Reports'!$L22) -> 0 | E22: =+D22+C22 -> 0 | L22: 8
B23: September | C23: =++COUNTIFS('Data Source'!$F:$F,'Statistic Reports'!C$14,'Data Source'!$BJ:$BJ,'Statistic Reports'!$L23) -> 0 | D23: =++COUNTIFS('Data Source'!$F:$F,'Statistic Reports'!D$14,'Data Source'!$BJ:$BJ,'Statistic Reports'!$L23) -> 0 | E23: =+D23+C23 -> 0 | L23: 9
B24: October | C24: =++COUNTIFS('Data Source'!$F:$F,'Statistic Reports'!C$14,'Data Source'!$BJ:$BJ,'Statistic Reports'!$L24) -> 0 | D24: =++COUNTIFS('Data Source'!$F:$F,'Statistic Reports'!D$14,'Data Source'!$BJ:$BJ,'Statistic Reports'!$L24) -> 0 | E24: =+D24+C24 -> 0 | L24: 10
B25: November | C25: =++COUNTIFS('Data Source'!$F:$F,'Statistic Reports'!C$14,'Data Source'!$BJ:$BJ,'Statistic Reports'!$L25) -> 0 | D25: =++COUNTIFS('Data Source'!$F:$F,'Statistic Reports'!D$14,'Data Source'!$BJ:$BJ,'Statistic Reports'!$L25) -> 0 | E25: =+D25+C25 -> 0 | L25: 11
B26: December | C26: =++COUNTIFS('Data Source'!$F:$F,'Statistic Reports'!C$14,'Data Source'!$BJ:$BJ,'Statistic Reports'!$L26) -> 0 | D26: =++COUNTIFS('Data Source'!$F:$F,'Statistic Reports'!D$14,'Data Source'!$BJ:$BJ,'Statistic Reports'!$L26) -> 0 | E26: =+D26+C26 -> 0 | L26: 12
E27: =+#REF! -> #REF!
B28: Total | C28: =++SUM(C15:C26) -> 0 | D28: =++SUM(D15:D26) -> 0 | E28: =++SUM(E15:E26) -> 0
B71: Death Age Category
B73: AGE Category | C73: MALE | D73: FEMALE | E73: TOTAL | J73: Male | K73: Female | L73: Ref. Month No.
B74: Below 1 Year Old | C74: =++COUNTIFS('Data Source'!$F:$F,'Statistic Reports'!C$73,'Data Source'!$BL:$BL,"<="&'Statistic Reports'!$L74,'Data Source'!$BL:$BL,"<="&'Statistic Reports'!$M74) -> 0 | D74: =++COUNTIFS('Data Source'!$F:$F,'Statistic Reports'!D$73,'Data Source'!$BL:$BL,"<="&'Statistic Reports'!$L74,'Data Source'!$BL:$BL,"<="&'Statistic Reports'!$M74) -> 0 | E74: =+D74+C74 -> 0 | J74: AA | K74: AA | L74: 0 | M74: 0
B75: 1 - 4 | C75: =++COUNTIFS('Data Source'!$F:$F,'Statistic Reports'!C$73,'Data Source'!$BL:$BL,">="&'Statistic Reports'!$L75,'Data Source'!$BL:$BL,"<="&'Statistic Reports'!$M75) -> 0 | D75: =++COUNTIFS('Data Source'!$F:$F,'Statistic Reports'!D$73,'Data Source'!$BL:$BL,">="&'Statistic Reports'!$L75,'Data Source'!$BL:$BL,"<="&'Statistic Reports'!$M75) -> 0 | E75: =+D75+C75 -> 0 | L75: 1 | M75: 4
B76: 5 - 9 | C76: =++COUNTIFS('Data Source'!$F:$F,'Statistic Reports'!C$73,'Data Source'!$BL:$BL,">="&'Statistic Reports'!$L76,'Data Source'!$BL:$BL,"<="&'Statistic Reports'!$M76) -> 0 | D76: =++COUNTIFS('Data Source'!$F:$F,'Statistic Reports'!D$73,'Data Source'!$BL:$BL,">="&'Statistic Reports'!$L76,'Data Source'!$BL:$BL,"<="&'Statistic Reports'!$M76) -> 0 | E76: =+D76+C76 -> 0 | L76: =+M75+1 -> 5 | M76: =+L76+4 -> 9
B77: 10 - 14 | C77: =++COUNTIFS('Data Source'!$F:$F,'Statistic Reports'!C$73,'Data Source'!$BL:$BL,">="&'Statistic Reports'!$L77,'Data Source'!$BL:$BL,"<="&'Statistic Reports'!$M77) -> 0 | D77: =++COUNTIFS('Data Source'!$F:$F,'Statistic Reports'!D$73,'Data Source'!$BL:$BL,">="&'Statistic Reports'!$L77,'Data Source'!$BL:$BL,"<="&'Statistic Reports'!$M77) -> 0 | E77: =+D77+C77 -> 0 | L77: =+M76+1 -> 10 | M77: =+L77+4 -> 14
B78: 15 - 19 | C78: =++COUNTIFS('Data Source'!$F:$F,'Statistic Reports'!C$73,'Data Source'!$BL:$BL,">="&'Statistic Reports'!$L78,'Data Source'!$BL:$BL,"<="&'Statistic Reports'!$M78) -> 0 | D78: =++COUNTIFS('Data Source'!$F:$F,'Statistic Reports'!D$73,'Data Source'!$BL:$BL,">="&'Statistic Reports'!$L78,'Data Source'!$BL:$BL,"<="&'Statistic Reports'!$M78) -> 0 | E78: =+D78+C78 -> 0 | L78: =+M77+1 -> 15 | M78: =+L78+4 -> 19
B79: 20 - 24 | C79: =++COUNTIFS('Data Source'!$F:$F,'Statistic Reports'!C$73,'Data Source'!$BL:$BL,">="&'Statistic Reports'!$L79,'Data Source'!$BL:$BL,"<="&'Statistic Reports'!$M79) -> 0 | D79: =++COUNTIFS('Data Source'!$F:$F,'Statistic Reports'!D$73,'Data Source'!$BL:$BL,">="&'Statistic Reports'!$L79,'Data Source'!$BL:$BL,"<="&'Statistic Reports'!$M79) -> 0 | E79: =+D79+C79 -> 0 | L79: =+M78+1 -> 20 | M79: =+L79+4 -> 24
B80: 25 - 29 | C80: =++COUNTIFS('Data Source'!$F:$F,'Statistic Reports'!C$73,'Data Source'!$BL:$BL,">="&'Statistic Reports'!$L80,'Data Source'!$BL:$BL,"<="&'Statistic Reports'!$M80) -> 0 | D80: =++COUNTIFS('Data Source'!$F:$F,'Statistic Reports'!D$73,'Data Source'!$BL:$BL,">="&'Statistic Reports'!$L80,'Data Source'!$BL:$BL,"<="&'Statistic Reports'!$M80) -> 0 | E80: =+D80+C80 -> 0 | L80: =+M79+1 -> 25 | M80: =+L80+4 -> 29
B81: 30 - 34 | C81: =++COUNTIFS('Data Source'!$F:$F,'Statistic Reports'!C$73,'Data Source'!$BL:$BL,">="&'Statistic Reports'!$L81,'Data Source'!$BL:$BL,"<="&'Statistic Reports'!$M81) -> 0 | D81: =++COUNTIFS('Data Source'!$F:$F,'Statistic Reports'!D$73,'Data Source'!$BL:$BL,">="&'Statistic Reports'!$L81,'Data Source'!$BL:$BL,"<="&'Statistic Reports'!$M81) -> 0 | E81: =+D81+C81 -> 0 | L81: =+M80+1 -> 30 | M81: =+L81+4 -> 34
B82: 35 - 39 | C82: =++COUNTIFS('Data Source'!$F:$F,'Statistic Reports'!C$73,'Data Source'!$BL:$BL,">="&'Statistic Reports'!$L82,'Data Source'!$BL:$BL,"<="&'Statistic Reports'!$M82) -> 0 | D82: =++COUNTIFS('Data Source'!$F:$F,'Statistic Reports'!D$73,'Data Source'!$BL:$BL,">="&'Statistic Reports'!$L82,'Data Source'!$BL:$BL,"<="&'Statistic Reports'!$M82) -> 0 | E82: =+D82+C82 -> 0 | L82: =+M81+1 -> 35 | M82: =+L82+4 -> 39
B83: 40 - 44 | C83: =++COUNTIFS('Data Source'!$F:$F,'Statistic Reports'!C$73,'Data Source'!$BL:$BL,">="&'Statistic Reports'!$L83,'Data Source'!$BL:$BL,"<="&'Statistic Reports'!$M83) -> 0 | D83: =++COUNTIFS('Data Source'!$F:$F,'Statistic Reports'!D$73,'Data Source'!$BL:$BL,">="&'Statistic Reports'!$L83,'Data Source'!$BL:$BL,"<="&'Statistic Reports'!$M83) -> 0 | E83: =+D83+C83 -> 0 | L83: =+M82+1 -> 40 | M83: =+L83+4 -> 44
B84: 45 - 49 | C84: =++COUNTIFS('Data Source'!$F:$F,'Statistic Reports'!C$73,'Data Source'!$BL:$BL,">="&'Statistic Reports'!$L84,'Data Source'!$BL:$BL,"<="&'Statistic Reports'!$M84) -> 0 | D84: =++COUNTIFS('Data Source'!$F:$F,'Statistic Reports'!D$73,'Data Source'!$BL:$BL,">="&'Statistic Reports'!$L84,'Data Source'!$BL:$BL,"<="&'Statistic Reports'!$M84) -> 0 | E84: =+D84+C84 -> 0 | L84: =+M83+1 -> 45 | M84: =+L84+4 -> 49
B85: 50 - 54 | C85: =++COUNTIFS('Data Source'!$F:$F,'Statistic Reports'!C$73,'Data Source'!$BL:$BL,">="&'Statistic Reports'!$L85,'Data Source'!$BL:$BL,"<="&'Statistic Reports'!$M85) -> 0 | D85: =++COUNTIFS('Data Source'!$F:$F,'Statistic Reports'!D$73,'Data Source'!$BL:$BL,">="&'Statistic Reports'!$L85,'Data Source'!$BL:$BL,"<="&'Statistic Reports'!$M85) -> 0 | E85: =+D85+C85 -> 0 | L85: =+M84+1 -> 50 | M85: =+L85+4 -> 54
B86: 55 - 59 | C86: =++COUNTIFS('Data Source'!$F:$F,'Statistic Reports'!C$73,'Data Source'!$BL:$BL,">="&'Statistic Reports'!$L86,'Data Source'!$BL:$BL,"<="&'Statistic Reports'!$M86) -> 0 | D86: =++COUNTIFS('Data Source'!$F:$F,'Statistic Reports'!D$73,'Data Source'!$BL:$BL,">="&'Statistic Reports'!$L86,'Data Source'!$BL:$BL,"<="&'Statistic Reports'!$M86) -> 0 | E86: =+D86+C86 -> 0 | L86: =+M85+1 -> 55 | M86: =+L86+4 -> 59
B87: 60 - 64 | C87: =++COUNTIFS('Data Source'!$F:$F,'Statistic Reports'!C$73,'Data Source'!$BL:$BL,">="&'Statistic Reports'!$L87,'Data Source'!$BL:$BL,"<="&'Statistic Reports'!$M87) -> 0 | D87: =++COUNTIFS('Data Source'!$F:$F,'Statistic Reports'!D$73,'Data Source'!$BL:$BL,">="&'Statistic Reports'!$L87,'Data Source'!$BL:$BL,"<="&'Statistic Reports'!$M87) -> 0 | E87: =+D87+C87 -> 0 | L87: =+M86+1 -> 60 | M87: =+L87+4 -> 64
... B90: 75 - 79 | C90: =++COUNTIFS('Data Source'!$F:$F,'Statistic Reports'!C$73,'Data Source'!$BL:$BL,">="&'Statistic Reports'!$L90,'Data Source'!$BL:$BL,"<="&'Statistic Reports'!$M90) -> 0 | D90: =++COUNTIFS('Data Source'!$F:$F,'Statistic Reports'!D$73,'Data Source'!$BL:$BL,">="&'Statistic Reports'!$L90,'Data Source'!$BL:$BL,"<="&'Statistic Reports'!$M90) -> 0 | E90: =+D90+C90 -> 0 | L90: =+M89+1 -> 75 | M90: =+L90+4 -> 79
B91: 80 - 89 | C91: =++COUNTIFS('Data Source'!$F:$F,'Statistic Reports'!C$73,'Data Source'!$BL:$BL,">="&'Statistic Reports'!$L91,'Data Source'!$BL:$BL,"<="&'Statistic Reports'!$M91) -> 0 | D91: =++COUNTIFS('Data Source'!$F:$F,'Statistic Reports'!D$73,'Data Source'!$BL:$BL,">="&'Statistic Reports'!$L91,'Data Source'!$BL:$BL,"<="&'Statistic Reports'!$M91) -> 0 | E91: =+D91+C91 -> 0 | L91: =+M90+1 -> 80 | M91: 89
B92: 90 - 99 | C92: =++COUNTIFS('Data Source'!$F:$F,'Statistic Reports'!C$73,'Data Source'!$BL:$BL,">="&'Statistic Reports'!$L92,'Data Source'!$BL:$BL,"<="&'Statistic Reports'!$M92) -> 0 | D92: =++COUNTIFS('Data Source'!$F:$F,'Statistic Reports'!D$73,'Data Source'!$BL:$BL,">="&'Statistic Reports'!$L92,'Data Source'!$BL:$BL,"<="&'Statistic Reports'!$M92) -> 0 | E92: =+D92+C92 -> 0 | L92: =+M91+1 -> 90 | M92: =+L92+9 -> 99
B93: 100 - Above | C93: =++COUNTIFS('Data Source'!$F:$F,'Statistic Reports'!C$73,'Data Source'!$BL:$BL,">="&'Statistic Reports'!$L93,'Data Source'!$BL:$BL,"<="&'Statistic Reports'!$M93) -> 0 | D93: =++COUNTIFS('Data Source'!$F:$F,'Statistic Reports'!D$73,'Data Source'!$BL:$BL,">="&'Statistic Reports'!$L93,'Data Source'!$BL:$BL,"<="&'Statistic Reports'!$M93) -> 0 | E93: =+D93+C93 -> 0 | L93: =+M92+1 -> 100 | M93: Above
...

Sheet ByMunicipality
B2: HEADING 1
B4: HEADING 2
B8: ='Data Source'!BI2 & " : " & " DEATH REGISTRATION BY MUNICIPALITY REPORTS" -> : DEATH REGISTRATION BY MUNICIPALITY REPORTS
B11: MUNICIPALITY SUMMARY
B13: No. | C13: Municipality Name | D13: Province | E13: Country | F13: MALE | G13: FEMALE | H13: TOTAL

Sheet CauseOfDeath
A4: CAUSE OF DEATH
A6: No. | B6: Reg. No. | C6: Last Name | D6: First Name | E6: Middle Name | F6: Date of Death | G6: Cause Immediate | H6: Cause Antecedent | I6: Cause Underlying | J6: Cause Underlying Interval | K6: Cause Other

Sheet DeadonArrival
B5: DEAD ON ARRIVAL SUMMARY
B8: No. | C8: Reg. No. | D8: Last Name | E8: First Name | F8: Middle Name | G8: Date of Death
